<?xml version="1.0" encoding="UTF-8"?>
<sdf version='1.9'>
  <model name='x500_passive_rotating_prop'>
    <self_collide>false</self_collide>
     <include merge='true'>
      <uri>x500</uri>
    </include>
    <include merge='true'>
      <uri>model://LW20</uri>
      <pose relative_to="base_link">0 0 -0.079 0 1.57 0</pose>
    </include>
    <joint name="lidar_model_joint" type="fixed">
      <parent>base_link</parent>
      <child>lw20_link</child>
      <pose relative_to="base_link">-0 0 0 0 0 0</pose>
    </joint>
    <joint name="lidar_sensor_joint" type="fixed">
      <parent>base_link</parent>
      <child>lidar_sensor_link</child>
    </joint>
    <link name="lidar_sensor_link">
      <pose relative_to="base_link">0 0 -0.05 0 1.57  0</pose>
      <inertial>
        <mass>0.001</mass>
        <inertia>
          <ixx>0.00001</ixx>
          <iyy>0.00001</iyy>
          <izz>0.00001</izz>
          <ixy>0.0</ixy>
          <ixz>0.0</ixz>
          <iyz>0.0</iyz>
        </inertia>
      </inertial>
      <sensor name='lidar' type='gpu_lidar'>"
        <pose>0 0 0 3.14 0 0</pose>
        <update_rate>50</update_rate>
        <ray>
            <scan>
                <horizontal>
                    <samples>1</samples>
                    <resolution>1</resolution>
                    <min_angle>0</min_angle>
                    <max_angle>0</max_angle>
                </horizontal>
                <vertical>
                    <samples>1</samples>
                    <resolution>1</resolution>
                    <min_angle>0</min_angle>
                    <max_angle>0</max_angle>
                </vertical>
            </scan>
            <range>
                <min>0.1</min>
                <max>100.0</max>
                <resolution>0.01</resolution>
            </range>
        </ray>
        <always_on>1</always_on>
        <visualize>true</visualize>
      </sensor>
    </link>

    <!-- Add a propeller guard -->
    <link name="propeller_guard">
      <pose>0 0 0.3 0 0 0</pose> <!-- Adjust the height as needed -->
      <inertial>
        <mass>0.1</mass>
        <inertia>
          <ixx>0.001</ixx>
          <iyy>0.001</iyy>
          <izz>0.001</izz>
        </inertia>
      </inertial>
      <visual name="propeller_guard_visual">
        <geometry>
          <cylinder>
            <radius>0.39</radius>
            <length>0.026</length>
          </cylinder>
        </geometry>
        <material>
          <ambient>1 1 1 0.5</ambient> <!-- White with 50% transparency -->
          <diffuse>1 1 1 0.5</diffuse> <!-- White with 50% transparency -->
          <specular>1 1 1 0.5</specular> <!-- White with 50% transparency -->
        </material>
      </visual>
      <!-- Add some visual markers to the propeller guard -->
      <visual name="propeller_guard_marker_1">
        <pose>0.364 0 0.013 0 0 0</pose>
        <geometry>
          <box>
            <size>0.026 0.13 0.013</size>
          </box>
        </geometry>
        <material>
          <ambient>0 0 0 1</ambient>
          <diffuse>0 0 0 1</diffuse>
          <specular>0.5 0.5 0.5 1</specular>
        </material>
      </visual>
      <visual name="propeller_guard_marker_2">
        <pose>-0.364 0 0.013 0 0 0</pose>
        <geometry>
          <box>
            <size>0.026 0.13 0.013</size>
          </box>
        </geometry>
        <material>
          <ambient>0 0 0 1</ambient>
          <diffuse>0 0 0 1</diffuse>
          <specular>0.5 0.5 0.5 1</specular>
        </material>
      </visual>
      <collision name="propeller_guard_collision">
        <geometry>
          <cylinder>
            <radius>0.39</radius>
            <length>0.026</length>
          </cylinder>
        </geometry>
      </collision>
    </link>
    <joint name="propeller_guard_joint" type="revolute">
      <parent>base_link</parent>
      <child>propeller_guard</child>
      <axis>
        <xyz>0 0 1</xyz>
        <limit>
          <lower>-1e+16</lower>
          <upper>1e+16</upper>
        </limit>
        <dynamics>
          <damping>0.001</damping>
          <friction>0.001</friction>
        </dynamics>
      </axis>

     <sensor name="propeller_guard_joint_ft_sensor" type="force_torque">
        <update_rate>1000</update_rate>
        <always_on>true</always_on>
        <topic>~/propeller_guard_joint/force_torque</topic>
        <force_torque>
          <frame>child</frame>
          <measure_direction>child_to_parent</measure_direction>
        </force_torque>
      </sensor>
    </joint>

    <!-- Add the Joint State Publisher system -->
    <plugin filename="gz-sim-joint-state-publisher-system" name="gz::sim::systems::JointStatePublisher">
        <topic>~/propeller_guard_joint/joint_state</topic>
        <joint_name>propeller_guard_joint</joint_name>
    </plugin>

  </model>
</sdf>
